<mujoco model='Franka-door'>

    <option gravity='0 0 0'/>
    <default>
         <geom margin='0.001' solref='0.002 1' solimp='0.8 0.8 0.1'/>
    </default>

    <compiler inertiafromgeom='true' angle='radian' meshdir="meshes/"/>

    <include file="franka-assets.xml"/>

    <worldbody>
        <!-- Floor -->
        <geom name='floor' pos='0 0 0' size='2 2 .01' type='plane' material="MatPlane" contype='4'/>
        <!-- Lighting -->
        <light directional='false' diffuse='.7 .7 .7' specular='0.03 0.03 0.03' pos='-1 -1.0 4.0' dir='1 1.0 -4'/>

        <!-- Robot -->
        <body name="robot" pos="0 0 0">
            <include file="franka.xml"/>
        </body>
        <!-- Door -->
        <!-- <body name='Door' pos='0.85 0.2 0.51' euler='0 0 0' user="1001 0 2002 -0.4 -0.1 0.252 0 0.3 0.45"> -->
        <body name='handle' pos='0.6 0.2 0.31' euler='0 0 3.1415'  user="1001 0 2002 -0.4 -0.1 0.252 0 0.3 0.45">
            <inertial pos='0 0 0' mass='0.2' />
            <joint name='articulation' pos='0 0.3 0' axis='0 0 1' type='hinge' range='-1.7 1.7' frictionloss='1'/>
            <!-- <geom name='box' type='cylinder' size='0.2 0.01 0.01' euler='0 1.57 0'/> -->
            <geom name='handle' type='cylinder' size='0.01 0.1 0.01' pos='0 0 0' euler='0 0 0'/>
            <site name='handle' pos='0 0 0' size='0.02' rgba='0 1 0 0.125'/>
        </body>


    </worldbody>


    <sensor>
        <jointpos name='joint1' joint='joint1'/>
        <jointpos name='joint2' joint='joint2'/>
        <jointpos name='joint3' joint='joint3'/>
        <jointpos name='joint4' joint='joint4'/>
        <jointpos name='joint5' joint='joint5'/>
        <jointpos name='joint6' joint='joint6'/>
        <jointpos name='joint7' joint='joint7'/>
        <jointpos name='finger1' joint='finger1'/>

        <jointvel name='vjoint1' joint='joint1'/>
        <jointvel name='vjoint2' joint='joint2'/>
        <jointvel name='vjoint3' joint='joint3'/>
        <jointvel name='vjoint4' joint='joint4'/>
        <jointvel name='vjoint5' joint='joint5'/>
        <jointvel name='vjoint6' joint='joint6'/>
        <jointvel name='vjoint7' joint='joint7'/>
        <jointvel name='vfinger1' joint='finger1'/>

        <framequat name='gripper_rot' objtype='site' objname='grasp'/>

        <framepos name='gripper_pos' objtype='site' objname='grasp'/>
        <framepos name='handle-pos' objtype='body' objname='handle'/>

    </sensor>

</mujoco>
