<mujocoinclude>
    <body name='link0' pos='0 0 0'>
        <geom name='vlink0' mesh='viz_link0' class='visual'/>
        <body name='link1' pos='0 0 0.333'>
            <joint name='joint1' pos='0 0 -0.333' range='-2.8973 2.8973'  />
            <geom name='vlink1' mesh='viz_link1' class='visual'/>
            <body name='link2' pos='0 0 0' euler='-1.5707 0 0' >
                <joint name='joint2' pos='0 0 0' range='-1.7628 1.7628'  />
                <geom name='vlink2' mesh='viz_link2' class='visual'/>
                <body name='link3' pos='0 -0.316 0' euler='1.5707 0 0' >
                    <joint name='joint3' pos='0 0 -0.12' range='-2.8973 2.8973' />
                    <geom name='vlink3' mesh='viz_link3' class='visual'/>
                    <body name='link4' pos='0.0825 0 0' euler='1.5707 0 0' >
                        <joint name='joint4' pos='0 0 0' range='-3.0718 -0.0698' />
                        <geom name='vlink4' mesh='viz_link4' class='visual'/>
                        <body name='link5' pos='-0.0825 0.384 0' euler='-1.5707 0 0' >
                            <joint name='joint5' pos='0 0 -0.26' range='-2.8973 2.9873' />
                            <geom name='vlink5' mesh='viz_link5' class='visual'/>
                            <body name='link6' pos='0 0 0' euler='1.5707 0 0' >
                                <joint name='joint6' pos='0 0 0' range='-0.0175 3.7525' />
                                <geom name='vlink6' mesh='viz_link6' class='visual'/>
                                <body name='link7' pos='0.088 0 0' euler='1.5707 0 0' >
                                    <joint name='joint7' pos='0 0 0' range='-2.8973 2.9873' />
                                    <geom name='vlink7' mesh='viz_link7' class='visual'/>
                                    <!-- Hand Start-->
                                    <body name='hand' pos='0 0 0.107' euler='0 0 0' >
                                        <site name='grasp' pos='0 0 0.08' size='0.01' rgba='0 1 0 0.125'/>
                                        <geom name='vhand' mesh='viz_hand' class='visual'/>
                                        <body name='finger1' pos='0 0 0.0584' euler='0 0 0' >
                                            <joint name='finger1' type='slide'
                                                    axis='0 1 0' pos='0 0 0' range='0.0 0.03' />
                                            <geom name='vf1' mesh='viz_finger' class='visual'/>
                                        </body>
                                        <body name='finger2' pos='0 0 0.0584' euler='0 0 -3.1415' >
                                            <joint name='finger2' type='slide'
                                                    axis='0 -1 0' pos='0 0 0' range='-0.03 0' />
                                            <geom name='vf2' mesh='viz_finger' class='visual'/>
                                        </body>
                                    </body>
                                    <!-- Hand End -->
                                </body>
                            </body>
                        </body>
                    </body>
                </body>
            </body>
        </body>
    </body>
</mujocoinclude>
